/home/runner/workspace/model_service.py:118: ExperimentalWarning: The live API is experimental and may change in future versions.
  async with client.aio.live.connect(model="gemini-2.0-flash-exp", config=config) as session:
2025-02-13 06:04:29,641 - model_service - INFO - Generated Python code:
print(default_api.get_patient_data(data_type='labs'))

2025-02-13 06:04:29,697 - model_service - INFO - Code execution result:
{'labResults': [{'interpretation': 'High', 'value': 6.8, 'date': '2024-01-15', 'test': 'HbA1c', 'referenceRange': '4.0-5.6', 'unit': '%'}, {'referenceRange': '125-200', 'interpretation': 'Normal', 'unit': 'mg/dL', 'test': 'Cholesterol', 'date': '2024-01-15', 'value': 185}, {'value': 55, 'test': 'HDL', 'unit': 'mg/dL', 'interpretation': 'Normal', 'date': '2024-01-15', 'referenceRange': '40-60'}, {'interpretation': 'Borderline High', 'referenceRange': '0-100', 'unit': 'mg/dL', 'test': 'LDL', 'date': '2024-01-15', 'value': 110}, {'interpretation': 'Normal', 'referenceRange': '0-150', 'test': 'Triglycerides', 'unit': 'mg/dL', 'date': '2024-01-15', 'value': 150}, {'interpretation': 'High', 'referenceRange': '70-100', 'date': '2024-01-15', 'unit': 'mg/dL', 'test': 'Fasting Glucose', 'value': 110}, {'referenceRange': '0.7-1.3', 'test': 'Creatinine', 'date': '2024-01-15', 'unit': 'mg/dL', 'interpretation': 'Normal', 'value': 1.1}]}

[graph_utils] Sending chart request to Node service: {'type': 'bar', 'data': {'labels': ['LDL'], 'datasets': [{'label': 'LDL Cholesterol', 'data': [110], 'backgroundColor': ['#36a2eb']}]}}
2025-02-13 06:04:31,402 - __main__ - ERROR - Graph generation/upload failed:
2025-02-13 06:04:31,404 - __main__ - ERROR - Traceback (most recent call last):
  File "/home/runner/workspace/graph_utils.py", line 28, in generate_graph
    response.raise_for_status()
  File "/home/runner/workspace/.pythonlibs/lib/python3.11/site-packages/requests/models.py", line 1024, in raise_for_status
    raise HTTPError(http_error_msg, response=self)
requests.exceptions.HTTPError: 500 Server Error: Internal Server Error for url: http://0.0.0.0:3001/render-chart

During handling of the above exception, another exception occurred:

Traceback (most recent call last):
  File "/home/runner/workspace/main.py", line 94, in send_rcs_message
    generate_graph(g_type, g_data)
  File "/home/runner/workspace/graph_utils.py", line 30, in generate_graph
    raise RuntimeError(f"Failed to contact chart service: {str(e)}")
RuntimeError: Failed to contact chart service: 500 Server Error: Internal Server Error for url: http://0.0.0.0:3001/render-chart