/home/runner/workspace/model_service.py:118: ExperimentalWarning: The live API is experimental and may change in future versions.
  async with client.aio.live.connect(model="gemini-2.0-flash-exp", config=config) as session:
2025-02-13 05:55:48,202 - model_service - INFO - Generated Python code:
patient_data = default_api.get_patient_data(data_type='labs')
print(patient_data)

2025-02-13 05:55:48,266 - model_service - INFO - Code execution result:
{'labResults': [{'value': 6.8, 'referenceRange': '4.0-5.6', 'test': 'HbA1c', 'date': '2024-01-15', 'unit': '%', 'interpretation': 'High'}, {'value': 185, 'date': '2024-01-15', 'unit': 'mg/dL', 'interpretation': 'Normal', 'referenceRange': '125-200', 'test': 'Cholesterol'}, {'date': '2024-01-15', 'interpretation': 'Normal', 'unit': 'mg/dL', 'value': 55, 'referenceRange': '40-60', 'test': 'HDL'}, {'interpretation': 'Borderline High', 'referenceRange': '0-100', 'date': '2024-01-15', 'unit': 'mg/dL', 'test': 'LDL', 'value': 110}, {'referenceRange': '0-150', 'date': '2024-01-15', 'unit': 'mg/dL', 'interpretation': 'Normal', 'value': 150, 'test': 'Triglycerides'}, {'referenceRange': '70-100', 'interpretation': 'High', 'date': '2024-01-15', 'unit': 'mg/dL', 'value': 110, 'test': 'Fasting Glucose'}, {'value': 1.1, 'test': 'Creatinine', 'referenceRange': '0.7-1.3', 'interpretation': 'Normal', 'unit': 'mg/dL', 'date': '2024-01-15'}]}

[graph_utils] Sending chart request to Node service: {'type': 'bar', 'data': {'labels': ['LDL'], 'datasets': [{'label': 'LDL Cholesterol', 'data': [110], 'backgroundColor': ['rgba(255, 99, 132, 0.2)'], 'borderColor': ['rgba(255, 99, 132, 1)'], 'borderWidth': 1}]}}
2025-02-13 05:55:50,431 - __main__ - ERROR - Graph generation/upload failed:
2025-02-13 05:55:50,431 - __main__ - ERROR - Traceback (most recent call last):
  File "/home/runner/workspace/graph_utils.py", line 28, in generate_graph
    response.raise_for_status()
  File "/home/runner/workspace/.pythonlibs/lib/python3.11/site-packages/requests/models.py", line 1024, in raise_for_status
    raise HTTPError(http_error_msg, response=self)
requests.exceptions.HTTPError: 500 Server Error: Internal Server Error for url: http://localhost:3001/render-chart

During handling of the above exception, another exception occurred:

Traceback (most recent call last):
  File "/home/runner/workspace/main.py", line 94, in send_rcs_message
    generate_graph(g_type, g_data)
  File "/home/runner/workspace/graph_utils.py", line 30, in generate_graph
    raise RuntimeError(f"Failed to contact chart service: {str(e)}")
RuntimeError: Failed to contact chart service: 500 Server Error: Internal Server Error for url: http://localhost:3001/render-chart

2025-02-13 05:55:51,398 - __main__ - ERROR - Failed to send RCS message: status_code: 400, body: {'errors': ['Error Code: invalid_type\nError Message: Required\nError Field: cards.0.buttons.0.title\nAdditional Info: {"expected":"string","received":"undefined"}\n', 'Error Code: invalid_type\nError Message: Required\nError Field: cards.0.buttons.0.type\nAdditional Info: {"expected":"\'openUrl\' | \'call\' | \'trigger\' | \'requestUserLocation\' | \'scheduleEvent\' | \'sendLocation\'","received":"undefined"}\n']}
2025-02-13 05:55:51,398 - __main__ - ERROR - Error processing user message: status_code: 400, body: {'errors': ['Error Code: invalid_type\nError Message: Required\nError Field: cards.0.buttons.0.title\nAdditional Info: {"expected":"string","received":"undefined"}\n', 'Error Code: invalid_type\nError Message: Required\nError Field: cards.0.buttons.0.type\nAdditional Info: {"expected":"\'openUrl\' | \'call\' | \'trigger\' | \'requestUserLocation\' | \'scheduleEvent\' | \'sendLocation\'","received":"undefined"}\n']}
2025-02-13 05:55:51,399 - __main__ - ERROR - Full traceback: Traceback (most recent call last):
  File "/home/runner/workspace/main.py", line 238, in handle_webhook
    send_rcs_message(from_number, response_data)
  File "/home/runner/workspace/main.py", line 137, in send_rcs_message
    rcs_response = client.send.rcs(**rcs_params)
                   ^^^^^^^^^^^^^^^^^^^^^^^^^^^^^
  File "/home/runner/workspace/.pythonlibs/lib/python3.11/site-packages/rcs/send/client.py", line 139, in rcs
    raise BadRequestError(
rcs.errors.bad_request_error.BadRequestError: status_code: 400, body: {'errors': ['Error Code: invalid_type\nError Message: Required\nError Field: cards.0.buttons.0.title\nAdditional Info: {"expected":"string","received":"undefined"}\n', 'Error Code: invalid_type\nError Message: Required\nError Field: cards.0.buttons.0.type\nAdditional Info: {"expected":"\'openUrl\' | \'call\' | \'trigger\' | \'requestUserLocation\' | \'scheduleEvent\' | \'sendLocation\'","received":"undefined"}\n']}