=====================


=== Graph Generation Debug ===
Response data keys: dict_keys(['text', 'cards', 'quick_replies', 'graph'])
Graph data found: {
  "type": "bar",
  "data": {
    "labels": [
      "HDL"
    ],
    "values": [
      55
    ],
    "title": "HDL Cholesterol",
    "xlabel": "Test",
    "ylabel": "mg/dL",
    "referenceLines": {
      "HDL": [
        40,
        60
      ]
    }
  }
}
Attempting to generate bar graph with data:
{
  "labels": [
    "HDL"
  ],
  "values": [
    55
  ],
  "title": "HDL Cholesterol",
  "xlabel": "Test",
  "ylabel": "mg/dL",
  "referenceLines": {
    "HDL": [
      40,
      60
    ]
  }
}
2025-02-04 02:08:43,462 - graph_utils - ERROR - Error generating graph: HTTPConnectionPool(host='0.0.0.0', port=3001): Max retries exceeded with url: /render-chart (Caused by NewConnectionError('<urllib3.connection.HTTPConnection object at 0x7f2d1853b7d0>: Failed to establish a new connection: [Errno 111] Connection refused'))
2025-02-04 02:08:43,463 - __main__ - ERROR - Graph generation/upload failed:
2025-02-04 02:08:43,463 - __main__ - ERROR - Error type: ValueError
2025-02-04 02:08:43,463 - __main__ - ERROR - Error message: Failed to generate graph: HTTPConnectionPool(host='0.0.0.0', port=3001): Max retries exceeded with url: /render-chart (Caused by NewConnectionError('<urllib3.connection.HTTPConnection object at 0x7f2d1853b7d0>: Failed to establish a new connection: [Errno 111] Connection refused'))
2025-02-04 02:08:43,467 - __main__ - ERROR - Traceback: Traceback (most recent call last):
  File "/home/runner/workspace/.pythonlibs/lib/python3.11/site-packages/urllib3/connection.py", line 198, in _new_conn
    sock = connection.create_connection(
           ^^^^^^^^^^^^^^^^^^^^^^^^^^^^^
  File "/home/runner/workspace/.pythonlibs/lib/python3.11/site-packages/urllib3/util/connection.py", line 85, in create_connection
    raise err
  File "/home/runner/workspace/.pythonlibs/lib/python3.11/site-packages/urllib3/util/connection.py", line 73, in create_connection
    sock.connect(sa)
ConnectionRefusedError: [Errno 111] Connection refused

The above exception was the direct cause of the following exception:

Traceback (most recent call last):
  File "/home/runner/workspace/.pythonlibs/lib/python3.11/site-packages/urllib3/connectionpool.py", line 787, in urlopen
    response = self._make_request(
               ^^^^^^^^^^^^^^^^^^^
  File "/home/runner/workspace/.pythonlibs/lib/python3.11/site-packages/urllib3/connectionpool.py", line 493, in _make_request
    conn.request(
  File "/home/runner/workspace/.pythonlibs/lib/python3.11/site-packages/urllib3/connection.py", line 445, in request
    self.endheaders()
  File "/nix/store/clx0mcir7qw8zk36zbr4jra789g3knf6-python3-3.11.10/lib/python3.11/http/client.py", line 1298, in endheaders
    self._send_output(message_body, encode_chunked=encode_chunked)
  File "/nix/store/clx0mcir7qw8zk36zbr4jra789g3knf6-python3-3.11.10/lib/python3.11/http/client.py", line 1058, in _send_output
    self.send(msg)
  File "/nix/store/clx0mcir7qw8zk36zbr4jra789g3knf6-python3-3.11.10/lib/python3.11/http/client.py", line 996, in send
    self.connect()
  File "/home/runner/workspace/.pythonlibs/lib/python3.11/site-packages/urllib3/connection.py", line 276, in connect
    self.sock = self._new_conn()
                ^^^^^^^^^^^^^^^^
  File "/home/runner/workspace/.pythonlibs/lib/python3.11/site-packages/urllib3/connection.py", line 213, in _new_conn
    raise NewConnectionError(
urllib3.exceptions.NewConnectionError: <urllib3.connection.HTTPConnection object at 0x7f2d1853b7d0>: Failed to establish a new connection: [Errno 111] Connection refused

The above exception was the direct cause of the following exception:

Traceback (most recent call last):
  File "/home/runner/workspace/.pythonlibs/lib/python3.11/site-packages/requests/adapters.py", line 667, in send
    resp = conn.urlopen(
           ^^^^^^^^^^^^^
  File "/home/runner/workspace/.pythonlibs/lib/python3.11/site-packages/urllib3/connectionpool.py", line 841, in urlopen
    retries = retries.increment(
              ^^^^^^^^^^^^^^^^^^
  File "/home/runner/workspace/.pythonlibs/lib/python3.11/site-packages/urllib3/util/retry.py", line 519, in increment
    raise MaxRetryError(_pool, url, reason) from reason  # type: ignore[arg-type]
    ^^^^^^^^^^^^^^^^^^^^^^^^^^^^^^^^^^^^^^^^^^^^^^^^^^^
urllib3.exceptions.MaxRetryError: HTTPConnectionPool(host='0.0.0.0', port=3001): Max retries exceeded with url: /render-chart (Caused by NewConnectionError('<urllib3.connection.HTTPConnection object at 0x7f2d1853b7d0>: Failed to establish a new connection: [Errno 111] Connection refused'))

During handling of the above exception, another exception occurred:

Traceback (most recent call last):
  File "/home/runner/workspace/graph_utils.py", line 36, in generate_graph
    response = requests.post("http://0.0.0.0:3001/render-chart",
              ^^^^^^^^^^^^^^^^^^^^^^^^^^^^^^^^^^^^^^^^^^^^^^^^^
  File "/home/runner/workspace/.pythonlibs/lib/python3.11/site-packages/requests/api.py", line 115, in post
    return request("post", url, data=data, json=json, **kwargs)
           ^^^^^^^^^^^^^^^^^^^^^^^^^^^^^^^^^^^^^^^^^^^^^^^^^^^^
  File "/home/runner/workspace/.pythonlibs/lib/python3.11/site-packages/requests/api.py", line 59, in request
    return session.request(method=method, url=url, **kwargs)
           ^^^^^^^^^^^^^^^^^^^^^^^^^^^^^^^^^^^^^^^^^^^^^^^^^
  File "/home/runner/workspace/.pythonlibs/lib/python3.11/site-packages/requests/sessions.py", line 589, in request
    resp = self.send(prep, **send_kwargs)
           ^^^^^^^^^^^^^^^^^^^^^^^^^^^^^^
  File "/home/runner/workspace/.pythonlibs/lib/python3.11/site-packages/requests/sessions.py", line 703, in send
    r = adapter.send(request, **kwargs)
        ^^^^^^^^^^^^^^^^^^^^^^^^^^^^^^^
  File "/home/runner/workspace/.pythonlibs/lib/python3.11/site-packages/requests/adapters.py", line 700, in send
    raise ConnectionError(e, request=request)
requests.exceptions.ConnectionError: HTTPConnectionPool(host='0.0.0.0', port=3001): Max retries exceeded with url: /render-chart (Caused by NewConnectionError('<urllib3.connection.HTTPConnection object at 0x7f2d1853b7d0>: Failed to establish a new connection: [Errno 111] Connection refused'))

During handling of the above exception, another exception occurred:

Traceback (most recent call last):
  File "/home/runner/workspace/main.py", line 219, in send_rcs_message
    img_b64 = generate_graph(g_type, g_data)
              ^^^^^^^^^^^^^^^^^^^^^^^^^^^^^^
  File "/home/runner/workspace/graph_utils.py", line 42, in generate_graph
    raise ValueError(f"Failed to generate graph: {str(e)}")
ValueError: Failed to generate graph: HTTPConnectionPool(host='0.0.0.0', port=3001): Max retries exceeded with url: /render-chart (Caused by NewConnectionError('<urllib3.connection.HTTPConnection object at 0x7f2d1853b7d0>: Failed to establish a new connection: [Errno 111] Connection refused'))